<!DOCTYPE html><html lang="zh-CN"><head><meta charset="UTF-8"><meta name="viewport" content="width=device-width"><meta name="theme-color" content="#222"><meta name="generator" content="Hexo 5.4.2"><link rel="apple-touch-icon" sizes="180x180" href="/assets/apple-touch-icon.png"><link rel="icon" type="image/png" sizes="32x32" href="/assets/favicon-32x32.png"><link rel="icon" type="image/png" sizes="16x16" href="/assets/favicon-16x16.png"><link rel="mask-icon" href="/assets/safari-pinned-tab.svg" color="#222"><link rel="stylesheet" href="/css/main.css"><link rel="stylesheet" href="https://cdnjs.cloudflare.com/ajax/libs/font-awesome/6.4.0/css/all.min.css" integrity="sha256-HtsXJanqjKTc8vVQjO4YMhiqFoXkfBsjBWcX91T1jr8=" crossorigin="anonymous"><link rel="stylesheet" href="https://cdnjs.cloudflare.com/ajax/libs/animate.css/3.1.1/animate.min.css" integrity="sha256-PR7ttpcvz8qrF57fur/yAx1qXMFJeJFiA6pSzWi0OIE=" crossorigin="anonymous"><script class="next-config" data-name="main" type="application/json">{"hostname":"www.bennyhuo.com","root":"/","images":"/images","scheme":"Pisces","darkmode":false,"version":"8.15.1","exturl":false,"sidebar":{"position":"left","display":"post","padding":18,"offset":12},"copycode":{"enable":true,"style":"default"},"bookmark":{"enable":false,"color":"#222","save":"auto"},"mediumzoom":false,"lazyload":false,"pangu":false,"comments":{"style":"tabs","active":"gittalk","storage":true,"lazyload":false,"nav":null},"stickytabs":false,"motion":{"enable":true,"async":false,"transition":{"menu_item":"fadeInDown","post_block":"fadeIn","post_header":"fadeInDown","post_body":"fadeInDown","coll_header":"fadeInLeft","sidebar":"fadeInUp"}},"prism":false,"i18n":{"placeholder":"搜索...","empty":"没有找到任何搜索结果：${query}","hits_time":"找到 ${hits} 个搜索结果（用时 ${time} 毫秒）","hits":"找到 ${hits} 个搜索结果"}}</script><script src="/js/config.js"></script><meta name="description" content="异步代码的异常处理通常都比较让人头疼，而协程则再一次展现了它的威力。"><meta property="og:type" content="article"><meta property="og:title" content="破解 Kotlin 协程（4）：异常处理篇"><meta property="og:url" content="https://www.bennyhuo.com/2019/04/23/coroutine-exceptions/index.html"><meta property="og:site_name" content="Benny Huo"><meta property="og:description" content="异步代码的异常处理通常都比较让人头疼，而协程则再一次展现了它的威力。"><meta property="og:locale" content="zh_CN"><meta property="article:published_time" content="2019-04-23T00:00:00.000Z"><meta property="article:modified_time" content="2024-07-21T13:13:12.813Z"><meta property="article:author" content="Benny Huo"><meta property="article:tag" content="Kotlin Java IntelliJ Android 视频教程"><meta name="twitter:card" content="summary"><link rel="canonical" href="https://www.bennyhuo.com/2019/04/23/coroutine-exceptions/"><script class="next-config" data-name="page" type="application/json">{"sidebar":"","isHome":false,"isPost":true,"lang":"zh-CN","comments":true,"permalink":"https://www.bennyhuo.com/2019/04/23/coroutine-exceptions/","path":"/2019/04/23/coroutine-exceptions/","title":"破解 Kotlin 协程（4）：异常处理篇"}</script><script class="next-config" data-name="calendar" type="application/json">""</script><title>破解 Kotlin 协程（4）：异常处理篇 | Benny Huo</title><script src="/js/third-party/analytics/baidu-analytics.js"></script><script async src="https://hm.baidu.com/hm.js?8158efd7e8cf52cfb7d8420b33755ca8"></script><noscript><link rel="stylesheet" href="/css/noscript.css"></noscript></head><body itemscope itemtype="http://schema.org/WebPage" class="use-motion"><div class="headband"></div><main class="main"><div class="column"><header class="header" itemscope itemtype="http://schema.org/WPHeader"><div class="site-brand-container"><div class="site-nav-toggle"><div class="toggle" aria-label="切换导航栏" role="button"><span class="toggle-line"></span> <span class="toggle-line"></span> <span class="toggle-line"></span></div></div><div class="site-meta"><a href="/" class="brand" rel="start"><i class="logo-line"></i><p class="site-title">Benny Huo</p><i class="logo-line"></i></a><p class="site-subtitle" itemprop="description">学海无涯，其乐无穷</p></div><div class="site-nav-right"><div class="toggle popup-trigger" aria-label="搜索" role="button"></div></div></div><nav class="site-nav"><ul class="main-menu menu"><li class="menu-item menu-item-home"><a href="/" rel="section"><i class="fa fa-house fa-fw"></i>首页</a></li><li class="menu-item menu-item-专栏"><a href="/book/" rel="section"><i class="fa fa-book fa-fw"></i>专栏</a></li><li class="menu-item menu-item-网盘"><a href="https://drive.bennyhuo.com/" rel="section" target="_blank"><i class="fa fa-hard-drive fa-fw"></i>网盘</a></li><li class="menu-item menu-item-项目"><a href="/project/" rel="section"><i class="fa fa-diagram-project fa-fw"></i>项目</a></li><li class="menu-item menu-item-about"><a href="/about/" rel="section"><i class="fa fa-user fa-fw"></i>关于</a></li></ul></nav></header><aside class="sidebar"><div class="sidebar-inner sidebar-nav-active sidebar-toc-active"><ul class="sidebar-nav"><li class="sidebar-nav-toc">文章目录</li><li class="sidebar-nav-overview">站点概览</li></ul><div class="sidebar-panel-container"><div class="post-toc-wrap sidebar-panel"><div class="post-toc animated"><ol class="nav"><li class="nav-item nav-level-2"><a class="nav-link" href="#1-%E5%BC%95%E5%AD%90"><span class="nav-number">1.</span> <span class="nav-text">1. 引子</span></a></li><li class="nav-item nav-level-2"><a class="nav-link" href="#2-%E6%B7%BB%E5%8A%A0%E5%BC%82%E5%B8%B8%E5%A4%84%E7%90%86%E9%80%BB%E8%BE%91"><span class="nav-number">2.</span> <span class="nav-text">2. 添加异常处理逻辑</span></a></li><li class="nav-item nav-level-2"><a class="nav-link" href="#3-%E5%85%A8%E5%B1%80%E5%BC%82%E5%B8%B8%E5%A4%84%E7%90%86"><span class="nav-number">3.</span> <span class="nav-text">3. 全局异常处理</span></a></li><li class="nav-item nav-level-2"><a class="nav-link" href="#4-%E5%BC%82%E5%B8%B8%E4%BC%A0%E6%92%AD"><span class="nav-number">4.</span> <span class="nav-text">4. 异常传播</span></a><ol class="nav-child"><li class="nav-item nav-level-3"><a class="nav-link" href="#5-join-%E5%92%8C-await"><span class="nav-number">4.1.</span> <span class="nav-text">5. join 和 await</span></a></li><li class="nav-item nav-level-3"><a class="nav-link" href="#6-%E5%B0%8F%E7%BB%93"><span class="nav-number">4.2.</span> <span class="nav-text">6. 小结</span></a></li><li class="nav-item nav-level-3"><a class="nav-link" href="#%E9%99%84%E5%8A%A0%E8%AF%B4%E6%98%8E"><span class="nav-number">4.3.</span> <span class="nav-text">附加说明</span></a></li></ol></li><li class="nav-item nav-level-2"><a class="nav-link" href="#%E5%85%B3%E4%BA%8E%E4%BD%9C%E8%80%85"><span class="nav-number">5.</span> <span class="nav-text">关于作者</span></a></li></ol></div></div><div class="site-overview-wrap sidebar-panel"><div class="site-author animated" itemprop="author" itemscope itemtype="http://schema.org/Person"><img class="site-author-image" itemprop="image" alt="Benny Huo" src="/assets/avatar.jpg"><p class="site-author-name" itemprop="name">Benny Huo</p><div class="site-description" itemprop="description">Google 开发者专家（GDE）<br>《深入理解 Kotlin 协程》作者</div></div><div class="site-state-wrap animated"><nav class="site-state"><div class="site-state-item site-state-posts"><a href="/archives/"><span class="site-state-item-count">91</span> <span class="site-state-item-name">日志</span></a></div><div class="site-state-item site-state-tags"><a href="/tags/"><span class="site-state-item-count">71</span> <span class="site-state-item-name">标签</span></a></div></nav></div><div class="links-of-author animated"><span class="links-of-author-item"><a href="https://github.com/bennyhuo" title="GitHub → https:&#x2F;&#x2F;github.com&#x2F;bennyhuo" rel="noopener me" target="_blank"><i class="fab fa-github fa-fw"></i>GitHub</a> </span><span class="links-of-author-item"><a href="mailto:bennyhuo@kotliner.cn" title="E-Mail → mailto:bennyhuo@kotliner.cn" rel="noopener me" target="_blank"><i class="fa fa-envelope fa-fw"></i>E-Mail</a> </span><span class="links-of-author-item"><a href="https://space.bilibili.com/28615855" title="Bilibli → https:&#x2F;&#x2F;space.bilibili.com&#x2F;28615855" rel="noopener me" target="_blank"><i class="fa fa-play fa-fw"></i>Bilibli</a> </span><span class="links-of-author-item"><a href="https://www.youtube.com/@bennyhuo" title="YouTube → https:&#x2F;&#x2F;www.youtube.com&#x2F;@bennyhuo" rel="noopener me" target="_blank"><i class="fab fa-youtube fa-fw"></i>YouTube</a></span></div></div></div></div></aside></div><div class="main-inner post posts-expand"><div class="post-block"><article itemscope itemtype="http://schema.org/Article" class="post-content" lang="zh-CN"><link itemprop="mainEntityOfPage" href="https://www.bennyhuo.com/2019/04/23/coroutine-exceptions/"><span hidden itemprop="author" itemscope itemtype="http://schema.org/Person"><meta itemprop="image" content="/assets/avatar.jpg"><meta itemprop="name" content="Benny Huo"></span><span hidden itemprop="publisher" itemscope itemtype="http://schema.org/Organization"><meta itemprop="name" content="Benny Huo"><meta itemprop="description" content="Google 开发者专家（GDE）<br>《深入理解 Kotlin 协程》作者"></span><span hidden itemprop="post" itemscope itemtype="http://schema.org/CreativeWork"><meta itemprop="name" content="破解 Kotlin 协程（4）：异常处理篇 | Benny Huo"><meta itemprop="description" content=""></span><header class="post-header"><h1 class="post-title" itemprop="name headline">破解 Kotlin 协程（4）：异常处理篇</h1><div class="post-meta-container"><div class="post-meta"><span class="post-meta-item"><span class="post-meta-item-icon"><i class="far fa-calendar"></i> </span><span class="post-meta-item-text">发表于</span> <time title="创建时间：2019-04-23 00:00:00" itemprop="dateCreated datePublished" datetime="2019-04-23T00:00:00+00:00">2019-04-23</time> </span><span class="post-meta-item"><span class="post-meta-item-icon"><i class="far fa-calendar-check"></i> </span><span class="post-meta-item-text">更新于</span> <time title="修改时间：2024-07-21 13:13:12" itemprop="dateModified" datetime="2024-07-21T13:13:12+00:00">2024-07-21</time> </span><span id="/2019/04/23/coroutine-exceptions/" class="post-meta-item leancloud_visitors" data-flag-title="破解 Kotlin 协程（4）：异常处理篇" title="阅读次数"><span class="post-meta-item-icon"><i class="far fa-eye"></i> </span><span class="post-meta-item-text">阅读次数：</span> <span class="leancloud-visitors-count"></span> </span><span class="post-meta-break"></span> <span class="post-meta-item" title="本文字数"><span class="post-meta-item-icon"><i class="far fa-file-word"></i> </span><span class="post-meta-item-text">本文字数：</span> <span>12k</span> </span><span class="post-meta-item" title="阅读时长"><span class="post-meta-item-icon"><i class="far fa-clock"></i> </span><span class="post-meta-item-text">阅读时长 &asymp;</span> <span>21 分钟</span></span></div></div></header><div class="post-body" itemprop="articleBody"><blockquote><p>异步代码的异常处理通常都比较让人头疼，而协程则再一次展现了它的威力。</p></blockquote><span id="more"></span><ul><li><a href="https://www.bennyhuo.com/2019/03/31/kotlin-coroutines-00-forword/">破解 Kotlin 协程（0）：前言</a></li><li><a href="https://www.bennyhuo.com/2019/04/01/basic-coroutines/">破解 Kotlin 协程（1）：入门篇</a></li><li><a href="https://www.bennyhuo.com/2019/04/08/coroutines-start-mode/">破解 Kotlin 协程（2）：协程启动篇</a></li><li><a href="https://www.bennyhuo.com/2019/04/11/coroutine-dispatchers/">破解 Kotlin 协程（3）：协程调度篇</a></li><li><a href="https://www.bennyhuo.com/2019/04/23/coroutine-exceptions/">破解 Kotlin 协程（4）：异常处理篇</a></li><li><a href="https://www.bennyhuo.com/2019/04/30/coroutine-cancellation/">破解 Kotlin 协程（5）：协程取消篇</a></li><li><a href="https://www.bennyhuo.com/2019/05/07/coroutine-suspend/">破解 Kotlin 协程（6）：协程挂起篇</a></li><li><a href="https://www.bennyhuo.com/2019/05/26/coroutine-sequence/">破解 Kotlin 协程（7）：序列生成器篇</a></li><li><a href="https://www.bennyhuo.com/2019/05/27/coroutine-android/">破解 Kotlin 协程（8）：Android 篇</a></li><li><a href="https://www.bennyhuo.com/2019/09/16/coroutine-channel/">破解 Kotlin 协程（9）：Channel 篇</a></li><li><a href="https://www.bennyhuo.com/2020/02/03/coroutine-select/">破解 Kotlin 协程（10）：Select 篇</a></li><li><a href="https://www.bennyhuo.com/2020/03/14/coroutine-flow/">破解 Kotlin 协程（11）：Flow 篇</a></li><li><a href="https://www.bennyhuo.com/2019/10/19/coroutine-why-so-called-lightweight-thread/">破解 Kotlin 协程（12）：协程为什么被称为『轻量级线程』？</a></li><li><a href="https://www.bennyhuo.com/2019/12/01/coroutine-implementations/">破解 Kotlin 协程（13）：协程的几类常见的实现</a></li></ul><h2 id="1-引子"><a href="#1-引子" class="headerlink" title="1. 引子"></a>1. 引子</h2><p>我们在前面一篇文章当中提到了这样一个例子：</p><figure class="highlight kotlin"><table><tr><td class="gutter"><pre><span class="line">1</span><br><span class="line">2</span><br><span class="line">3</span><br><span class="line">4</span><br><span class="line">5</span><br></pre></td><td class="code"><pre><span class="line"><span class="keyword">typealias</span> Callback = (User) -&gt; <span class="built_in">Unit</span></span><br><span class="line"></span><br><span class="line"><span class="function"><span class="keyword">fun</span> <span class="title">getUser</span><span class="params">(callback: <span class="type">Callback</span>)</span></span>&#123;</span><br><span class="line">    ...</span><br><span class="line">&#125;</span><br></pre></td></tr></table></figure><p>我们通常会定义这样的回调接口来实现异步数据的请求，我们可以很方便的将它转换成协程的接口：</p><figure class="highlight kotlin"><table><tr><td class="gutter"><pre><span class="line">1</span><br><span class="line">2</span><br><span class="line">3</span><br><span class="line">4</span><br><span class="line">5</span><br><span class="line">6</span><br></pre></td><td class="code"><pre><span class="line"><span class="keyword">suspend</span> <span class="function"><span class="keyword">fun</span> <span class="title">getUserCoroutine</span><span class="params">()</span></span> = suspendCoroutine&lt;User&gt; &#123;</span><br><span class="line">    continuation -&gt;</span><br><span class="line">    getUser &#123;</span><br><span class="line">        continuation.resume(it)</span><br><span class="line">    &#125;</span><br><span class="line">&#125;</span><br></pre></td></tr></table></figure><p>并最终交给按钮点击事件或者其他事件去触发这个异步请求：</p><figure class="highlight kotlin"><table><tr><td class="gutter"><pre><span class="line">1</span><br><span class="line">2</span><br><span class="line">3</span><br><span class="line">4</span><br><span class="line">5</span><br></pre></td><td class="code"><pre><span class="line">getUserBtn.setOnClickListener &#123;</span><br><span class="line">    GlobalScope.launch(Dispatchers.Main) &#123;</span><br><span class="line">        userNameView.text = getUserCoroutine().name</span><br><span class="line">    &#125;</span><br><span class="line">&#125;</span><br></pre></td></tr></table></figure><p>那么问题来了，既然是请求，总会有失败的情形，而我们这里并没有对错误的处理，接下来我们就完善这个例子。</p><h2 id="2-添加异常处理逻辑"><a href="#2-添加异常处理逻辑" class="headerlink" title="2. 添加异常处理逻辑"></a>2. 添加异常处理逻辑</h2><p>首先我们加上异常回调接口函数：</p><figure class="highlight kotlin"><table><tr><td class="gutter"><pre><span class="line">1</span><br><span class="line">2</span><br><span class="line">3</span><br><span class="line">4</span><br><span class="line">5</span><br></pre></td><td class="code"><pre><span class="line"><span class="keyword">interface</span> <span class="title class_">Callback</span>&lt;<span class="type">T</span>&gt; &#123;</span><br><span class="line">    <span class="function"><span class="keyword">fun</span> <span class="title">onSuccess</span><span class="params">(value: <span class="type">T</span>)</span></span></span><br><span class="line"></span><br><span class="line">    <span class="function"><span class="keyword">fun</span> <span class="title">onError</span><span class="params">(t: <span class="type">Throwable</span>)</span></span></span><br><span class="line">&#125;</span><br></pre></td></tr></table></figure><p>接下来我们在改造一下我们的 <code>getUserCoroutine</code>：</p><figure class="highlight kotlin"><table><tr><td class="gutter"><pre><span class="line">1</span><br><span class="line">2</span><br><span class="line">3</span><br><span class="line">4</span><br><span class="line">5</span><br><span class="line">6</span><br><span class="line">7</span><br><span class="line">8</span><br><span class="line">9</span><br><span class="line">10</span><br><span class="line">11</span><br></pre></td><td class="code"><pre><span class="line"><span class="keyword">suspend</span> <span class="function"><span class="keyword">fun</span> <span class="title">getUserCoroutine</span><span class="params">()</span></span> = suspendCoroutine&lt;User&gt; &#123; continuation -&gt;</span><br><span class="line">    getUser(<span class="keyword">object</span> : Callback&lt;User&gt; &#123;</span><br><span class="line">        <span class="keyword">override</span> <span class="function"><span class="keyword">fun</span> <span class="title">onSuccess</span><span class="params">(value: <span class="type">User</span>)</span></span> &#123;</span><br><span class="line">            continuation.resume(value)</span><br><span class="line">        &#125;</span><br><span class="line"></span><br><span class="line">        <span class="keyword">override</span> <span class="function"><span class="keyword">fun</span> <span class="title">onError</span><span class="params">(t: <span class="type">Throwable</span>)</span></span> &#123;</span><br><span class="line">            continuation.resumeWithException(t)</span><br><span class="line">        &#125;</span><br><span class="line">    &#125;)</span><br><span class="line">&#125;</span><br></pre></td></tr></table></figure><p>大家可以看到，我们似乎就是完全把 <code>Callback</code> 转换成了一个 <code>Continuation</code>，在调用的时候我们只需要：</p><figure class="highlight kotlin"><table><tr><td class="gutter"><pre><span class="line">1</span><br><span class="line">2</span><br><span class="line">3</span><br><span class="line">4</span><br><span class="line">5</span><br><span class="line">6</span><br><span class="line">7</span><br></pre></td><td class="code"><pre><span class="line">GlobalScope.launch(Dispatchers.Main) &#123;</span><br><span class="line">    <span class="keyword">try</span> &#123;</span><br><span class="line">        userNameView.text = getUserCoroutine().name</span><br><span class="line">    &#125; <span class="keyword">catch</span> (e: Exception) &#123;</span><br><span class="line">        userNameView.text = <span class="string">&quot;Get User Error: <span class="variable">$e</span>&quot;</span></span><br><span class="line">    &#125;</span><br><span class="line">&#125;</span><br></pre></td></tr></table></figure><p>是的，你没看错，一个异步的请求异常，我们只需要在我们的代码中捕获就可以了，这样做的好处就是，请求的全流程异常都可以在一个 <code>try ... catch ...</code> 当中捕获，那么我们可以说真正做到了把异步代码变成了同步的写法。</p><p>如果你一直在用 RxJava 处理这样的逻辑，那么你的请求接口可能是这样的：</p><figure class="highlight kotlin"><table><tr><td class="gutter"><pre><span class="line">1</span><br><span class="line">2</span><br><span class="line">3</span><br><span class="line">4</span><br><span class="line">5</span><br><span class="line">6</span><br><span class="line">7</span><br><span class="line">8</span><br><span class="line">9</span><br><span class="line">10</span><br><span class="line">11</span><br><span class="line">12</span><br><span class="line">13</span><br></pre></td><td class="code"><pre><span class="line"><span class="function"><span class="keyword">fun</span> <span class="title">getUserObservable</span><span class="params">()</span></span>: Single&lt;User&gt; &#123;</span><br><span class="line">    <span class="keyword">return</span> Single.create&lt;User&gt; &#123; emitter -&gt;</span><br><span class="line">        getUser(<span class="keyword">object</span> : Callback&lt;User&gt; &#123;</span><br><span class="line">            <span class="keyword">override</span> <span class="function"><span class="keyword">fun</span> <span class="title">onSuccess</span><span class="params">(value: <span class="type">User</span>)</span></span> &#123;</span><br><span class="line">                emitter.onSuccess(value)</span><br><span class="line">            &#125;</span><br><span class="line"></span><br><span class="line">            <span class="keyword">override</span> <span class="function"><span class="keyword">fun</span> <span class="title">onError</span><span class="params">(t: <span class="type">Throwable</span>)</span></span> &#123;</span><br><span class="line">                emitter.onError(t)</span><br><span class="line">            &#125;</span><br><span class="line">        &#125;)</span><br><span class="line">    &#125;</span><br><span class="line">&#125;</span><br></pre></td></tr></table></figure><p>调用时大概是这样的：</p><figure class="highlight kotlin"><table><tr><td class="gutter"><pre><span class="line">1</span><br><span class="line">2</span><br><span class="line">3</span><br><span class="line">4</span><br><span class="line">5</span><br><span class="line">6</span><br><span class="line">7</span><br></pre></td><td class="code"><pre><span class="line">getUserObservable()</span><br><span class="line">        .observeOn(AndroidSchedulers.mainThread())</span><br><span class="line">        .subscribe (&#123; user -&gt;</span><br><span class="line">            userNameView.text = user.name</span><br><span class="line">        &#125;, &#123;</span><br><span class="line">            userNameView.text = <span class="string">&quot;Get User Error: <span class="variable">$it</span>&quot;</span></span><br><span class="line">        &#125;)</span><br></pre></td></tr></table></figure><p>其实你很容易就能发现在这里 RxJava 做的事儿跟协程的目的是一样的，只不过协程用了一种更自然的方式。</p><blockquote><p>也许你已经对 RxJava 很熟悉并且感到很自然，但相比之下，RxJava 的代码比协程的复杂度更高，更让人费解，这一点我们后面的文章中也会持续用例子来说明这一点。</p></blockquote><h2 id="3-全局异常处理"><a href="#3-全局异常处理" class="headerlink" title="3. 全局异常处理"></a>3. 全局异常处理</h2><p>线程也好、RxJava 也好，都有全局处理异常的方式，例如：</p><figure class="highlight kotlin"><table><tr><td class="gutter"><pre><span class="line">1</span><br><span class="line">2</span><br><span class="line">3</span><br><span class="line">4</span><br><span class="line">5</span><br><span class="line">6</span><br><span class="line">7</span><br><span class="line">8</span><br></pre></td><td class="code"><pre><span class="line"><span class="function"><span class="keyword">fun</span> <span class="title">main</span><span class="params">()</span></span> &#123;</span><br><span class="line">    Thread.setDefaultUncaughtExceptionHandler &#123;t: Thread, e: Throwable -&gt;</span><br><span class="line">        <span class="comment">//handle exception here</span></span><br><span class="line">        println(<span class="string">&quot;Thread &#x27;<span class="subst">$&#123;t.name&#125;</span>&#x27; throws an exception with message &#x27;<span class="subst">$&#123;e.message&#125;</span>&#x27;&quot;</span>)</span><br><span class="line">    &#125;</span><br><span class="line"></span><br><span class="line">    <span class="keyword">throw</span> ArithmeticException(<span class="string">&quot;Hey!&quot;</span>)</span><br><span class="line">&#125;</span><br></pre></td></tr></table></figure><p>我们可以为线程设置全局的异常捕获，当然也可以为 RxJava 来设置全局异常捕获：</p><figure class="highlight kotlin"><table><tr><td class="gutter"><pre><span class="line">1</span><br><span class="line">2</span><br><span class="line">3</span><br><span class="line">4</span><br></pre></td><td class="code"><pre><span class="line">RxJavaPlugins.setErrorHandler(e -&gt; &#123;</span><br><span class="line">        <span class="comment">//handle exception here</span></span><br><span class="line">        println(<span class="string">&quot;Throws an exception with message &#x27;<span class="subst">$&#123;e.message&#125;</span>&#x27;&quot;</span>)</span><br><span class="line">&#125;);</span><br></pre></td></tr></table></figure><p>协程显然也可以做到这一点。类似于通过 <code>Thread.setUncaughtExceptionHandler</code> 为线程设置一个异常捕获器，我们也可以为每一个协程单独设置 <code>CoroutineExceptionHandler</code>，这样协程内部未捕获的异常就可以通过它来捕获：</p><figure class="highlight kotlin"><table><tr><td class="gutter"><pre><span class="line">1</span><br><span class="line">2</span><br><span class="line">3</span><br><span class="line">4</span><br><span class="line">5</span><br><span class="line">6</span><br><span class="line">7</span><br><span class="line">8</span><br><span class="line">9</span><br><span class="line">10</span><br><span class="line">11</span><br></pre></td><td class="code"><pre><span class="line"><span class="keyword">private</span> <span class="keyword">suspend</span> <span class="function"><span class="keyword">fun</span> <span class="title">main</span><span class="params">()</span></span>&#123;</span><br><span class="line">    <span class="keyword">val</span> exceptionHandler = CoroutineExceptionHandler &#123; coroutineContext, throwable -&gt;</span><br><span class="line">        log(<span class="string">&quot;Throws an exception with message: <span class="subst">$&#123;throwable.message&#125;</span>&quot;</span>)</span><br><span class="line">    &#125;</span><br><span class="line"></span><br><span class="line">    log(<span class="number">1</span>)</span><br><span class="line">    GlobalScope.launch(exceptionHandler) &#123;</span><br><span class="line">        <span class="keyword">throw</span> ArithmeticException(<span class="string">&quot;Hey!&quot;</span>)</span><br><span class="line">    &#125;.join()</span><br><span class="line">    log(<span class="number">2</span>)</span><br><span class="line">&#125;</span><br></pre></td></tr></table></figure><p>运行结果：</p><figure class="highlight plaintext"><table><tr><td class="gutter"><pre><span class="line">1</span><br><span class="line">2</span><br><span class="line">3</span><br></pre></td><td class="code"><pre><span class="line">19:06:35:087 [main] 1</span><br><span class="line">19:06:35:208 [DefaultDispatcher-worker-1 @coroutine#1] Throws an exception with message: Hey!</span><br><span class="line">19:06:35:211 [DefaultDispatcher-worker-1 @coroutine#1] 2</span><br></pre></td></tr></table></figure><p><code>CoroutineExceptionHandler</code> 竟然也是一个上下文，协程的这个上下文可真是灵魂一般的存在，这倒是一点儿也不让人感到意外。</p><p>当然，这并不算是一个全局的异常捕获，因为它只能捕获对应协程内未捕获的异常，如果你想做到真正的全局捕获，在 Jvm 上我们可以自己定义一个捕获类实现：</p><figure class="highlight kotlin"><table><tr><td class="gutter"><pre><span class="line">1</span><br><span class="line">2</span><br><span class="line">3</span><br><span class="line">4</span><br><span class="line">5</span><br><span class="line">6</span><br><span class="line">7</span><br></pre></td><td class="code"><pre><span class="line"><span class="keyword">class</span> <span class="title class_">GlobalCoroutineExceptionHandler</span>: <span class="type">CoroutineExceptionHandler</span> &#123;</span><br><span class="line">    <span class="keyword">override</span> <span class="keyword">val</span> key: CoroutineContext.Key&lt;*&gt; = CoroutineExceptionHandler</span><br><span class="line"></span><br><span class="line">    <span class="keyword">override</span> <span class="function"><span class="keyword">fun</span> <span class="title">handleException</span><span class="params">(context: <span class="type">CoroutineContext</span>, exception: <span class="type">Throwable</span>)</span></span> &#123;</span><br><span class="line">        println(<span class="string">&quot;Coroutine exception: <span class="variable">$exception</span>&quot;</span>)</span><br><span class="line">    &#125;</span><br><span class="line">&#125;</span><br></pre></td></tr></table></figure><p>然后在 classpath 中创建 META-INF/services/kotlinx.coroutines.CoroutineExceptionHandler，文件名实际上就是 <code>CoroutineExceptionHandler</code> 的全类名，文件内容就写我们的实现类的全类名：</p><figure class="highlight plaintext"><table><tr><td class="gutter"><pre><span class="line">1</span><br></pre></td><td class="code"><pre><span class="line">com.bennyhuo.coroutines.sample2.exceptions.GlobalCoroutineExceptionHandler</span><br></pre></td></tr></table></figure><p>这样协程中没有被捕获的异常就会最终交给它处理。</p><blockquote><p>Jvm 上全局 <code>CoroutineExceptionHandler</code> 的配置，本质上是对 <code>ServiceLoader</code> 的应用，之前我们在讲 <code>Dispatchers.Main</code> 的时候提到过，Jvm 上它的实现也是通过 <code>ServiceLoader</code> 来加载的。</p></blockquote><p>需要明确的一点是，通过 <code>async</code> 启动的协程出现未捕获的异常时会忽略 <code>CoroutineExceptionHandler</code>，这与 <code>launch</code> 的设计思路是不同的。</p><h2 id="4-异常传播"><a href="#4-异常传播" class="headerlink" title="4. 异常传播"></a>4. 异常传播</h2><p>异常传播还涉及到协程作用域的概念，例如我们启动协程的时候一直都是用的 <code>GlobalScope</code>，意味着这是一个独立的顶级协程作用域，此外还有 <code>coroutineScope &#123; ... &#125;</code> 以及 <code>supervisorScope &#123; ... &#125;</code>。</p><ul><li>通过 GlobeScope 启动的协程单独启动一个协程作用域，内部的子协程遵从默认的作用域规则。通过 GlobeScope 启动的协程“自成一派”。</li><li>coroutineScope 是继承外部 Job 的上下文创建作用域，在其内部的取消操作是双向传播的，子协程未捕获的异常也会向上传递给父协程。它更适合一系列对等的协程并发的完成一项工作，任何一个子协程异常退出，那么整体都将退出，简单来说就是”一损俱损“。这也是协程内部再启动子协程的默认作用域。</li><li>supervisorScope 同样继承外部作用域的上下文，但其内部的取消操作是单向传播的，父协程向子协程传播，反过来则不然，这意味着子协程出了异常并不会影响父协程以及其他兄弟协程。它更适合一些独立不相干的任务，任何一个任务出问题，并不会影响其他任务的工作，简单来说就是”自作自受“，例如 UI，我点击一个按钮出了异常，其实并不会影响手机状态栏的刷新。需要注意的是，supervisorScope 内部启动的子协程内部再启动子协程，如无明确指出，则遵守默认作用域规则，也即 supervisorScope 只作用域其直接子协程。</li></ul><p>这么说还是比较抽象，因此我们拿一些例子来分析一下：</p><figure class="highlight kotlin"><table><tr><td class="gutter"><pre><span class="line">1</span><br><span class="line">2</span><br><span class="line">3</span><br><span class="line">4</span><br><span class="line">5</span><br><span class="line">6</span><br><span class="line">7</span><br><span class="line">8</span><br><span class="line">9</span><br><span class="line">10</span><br><span class="line">11</span><br><span class="line">12</span><br><span class="line">13</span><br><span class="line">14</span><br><span class="line">15</span><br><span class="line">16</span><br><span class="line">17</span><br><span class="line">18</span><br><span class="line">19</span><br><span class="line">20</span><br><span class="line">21</span><br><span class="line">22</span><br><span class="line">23</span><br><span class="line">24</span><br><span class="line">25</span><br><span class="line">26</span><br><span class="line">27</span><br><span class="line">28</span><br><span class="line">29</span><br><span class="line">30</span><br><span class="line">31</span><br><span class="line">32</span><br><span class="line">33</span><br></pre></td><td class="code"><pre><span class="line"><span class="keyword">suspend</span> <span class="function"><span class="keyword">fun</span> <span class="title">main</span><span class="params">()</span></span> &#123;</span><br><span class="line">    log(<span class="number">1</span>)</span><br><span class="line">    <span class="keyword">try</span> &#123;</span><br><span class="line">        coroutineScope &#123; <span class="comment">//①</span></span><br><span class="line">            log(<span class="number">2</span>)</span><br><span class="line">            launch &#123; <span class="comment">// ②</span></span><br><span class="line">                log(<span class="number">3</span>)</span><br><span class="line">                launch &#123; <span class="comment">// ③ </span></span><br><span class="line">                    log(<span class="number">4</span>)</span><br><span class="line">                    delay(<span class="number">100</span>)</span><br><span class="line">                    <span class="keyword">throw</span> ArithmeticException(<span class="string">&quot;Hey!!&quot;</span>)</span><br><span class="line">                &#125;</span><br><span class="line">                log(<span class="number">5</span>)</span><br><span class="line">            &#125;</span><br><span class="line">            log(<span class="number">6</span>)</span><br><span class="line">            <span class="keyword">val</span> job = launch &#123; <span class="comment">// ④</span></span><br><span class="line">                log(<span class="number">7</span>)</span><br><span class="line">                delay(<span class="number">1000</span>)</span><br><span class="line">            &#125;</span><br><span class="line">            <span class="keyword">try</span> &#123;</span><br><span class="line">                log(<span class="number">8</span>)</span><br><span class="line">                 job.join()</span><br><span class="line">                log(<span class="string">&quot;9&quot;</span>)</span><br><span class="line">            &#125; <span class="keyword">catch</span> (e: Exception) &#123;</span><br><span class="line">                log(<span class="string">&quot;10. <span class="variable">$e</span>&quot;</span>)</span><br><span class="line">            &#125;</span><br><span class="line">        &#125;</span><br><span class="line">        log(<span class="number">11</span>)</span><br><span class="line">    &#125; <span class="keyword">catch</span> (e: Exception) &#123;</span><br><span class="line">        log(<span class="string">&quot;12. <span class="variable">$e</span>&quot;</span>)</span><br><span class="line">    &#125;</span><br><span class="line">    log(<span class="number">13</span>)</span><br><span class="line">&#125;</span><br></pre></td></tr></table></figure><p>这例子稍微有点儿复杂，但也不难理解，我们在一个 <code>coroutineScope</code> 当中启动了两个协程 ②④，在 ② 当中启动了一个子协程 ③，作用域直接创建的协程记为①。那么 ③ 当中抛异常会发生什么呢？我们先来看下输出：</p><figure class="highlight plaintext"><table><tr><td class="gutter"><pre><span class="line">1</span><br><span class="line">2</span><br><span class="line">3</span><br><span class="line">4</span><br><span class="line">5</span><br><span class="line">6</span><br><span class="line">7</span><br><span class="line">8</span><br><span class="line">9</span><br><span class="line">10</span><br><span class="line">11</span><br></pre></td><td class="code"><pre><span class="line">11:37:36:208 [main] 1</span><br><span class="line">11:37:36:255 [main] 2</span><br><span class="line">11:37:36:325 [DefaultDispatcher-worker-1] 3</span><br><span class="line">11:37:36:325 [DefaultDispatcher-worker-1] 5</span><br><span class="line">11:37:36:326 [DefaultDispatcher-worker-3] 4</span><br><span class="line">11:37:36:331 [main] 6</span><br><span class="line">11:37:36:336 [DefaultDispatcher-worker-1] 7</span><br><span class="line">11:37:36:336 [main] 8</span><br><span class="line">11:37:36:441 [DefaultDispatcher-worker-1] 10. kotlinx.coroutines.JobCancellationException: ScopeCoroutine is cancelling; job=ScopeCoroutine&#123;Cancelling&#125;@2bc92d2f</span><br><span class="line">11:37:36:445 [DefaultDispatcher-worker-1] 12. java.lang.ArithmeticException: Hey!!</span><br><span class="line">11:37:36:445 [DefaultDispatcher-worker-1] 13</span><br></pre></td></tr></table></figure><p>注意两个位置，一个是 10，我们调用 <code>join</code>，收到了一个取消异常，在协程当中支持取消的操作的suspend方法在取消时会抛出一个 <code>CancellationException</code>，这类似于线程中对 <code>InterruptException</code> 的响应，遇到这种情况表示 <code>join</code> 调用所在的协程已经被取消了，那么这个取消究竟是怎么回事呢？</p><p>原来协程 ③ 抛出了未捕获的异常，进入了异常完成的状态，它与父协程 ② 之间遵循默认的作用域规则，因此 ③ 会通知它的父协程也就是 ② 取消，② 根据作用域规则通知父协程 ① 也就是整个作用域取消，这是一个自下而上的一次传播，这样身处 ① 当中的 <code>job.join</code> 调用就会抛异常，也就是 10 处的结果了。如果不是很理解这个操作，想一下我们说到的，<code>coroutineScope</code> 内部启动的协程就是“一损俱损”。实际上由于父协程 ① 被取消，协程④ 也不能幸免，如果大家有兴趣的话，也可以对 ④ 当中的 <code>delay</code>进行捕获，一样会收获一枚取消异常。</p><p>还有一个位置就是 12，这个是我们对 <code>coroutineScope</code> 整体的一个捕获，如果 <code>coroutineScope</code> 内部以为异常而结束，那么我们是可以对它直接 <code>try ... catch ...</code> 来捕获这个异常的，这再一次表明协程把异步的异常处理到同步代码逻辑当中。</p><p>那么如果我们把 <code>coroutineScope</code> 换成 <code>supervisorScope</code>，其他不变，运行结果会是怎样呢？</p><figure class="highlight plaintext"><table><tr><td class="gutter"><pre><span class="line">1</span><br><span class="line">2</span><br><span class="line">3</span><br><span class="line">4</span><br><span class="line">5</span><br><span class="line">6</span><br><span class="line">7</span><br><span class="line">8</span><br><span class="line">9</span><br><span class="line">10</span><br><span class="line">11</span><br><span class="line">12</span><br><span class="line">13</span><br><span class="line">14</span><br><span class="line">15</span><br><span class="line">16</span><br><span class="line">17</span><br><span class="line">18</span><br></pre></td><td class="code"><pre><span class="line">11:52:48:632 [main] 1</span><br><span class="line">11:52:48:694 [main] 2</span><br><span class="line">11:52:48:875 [main] 6</span><br><span class="line">11:52:48:892 [DefaultDispatcher-worker-1 @coroutine#1] 3</span><br><span class="line">11:52:48:895 [DefaultDispatcher-worker-1 @coroutine#1] 5</span><br><span class="line">11:52:48:900 [DefaultDispatcher-worker-3 @coroutine#3] 4</span><br><span class="line">11:52:48:905 [DefaultDispatcher-worker-2 @coroutine#2] 7</span><br><span class="line">11:52:48:907 [main] 8</span><br><span class="line">Exception in thread &quot;DefaultDispatcher-worker-3 @coroutine#3&quot; java.lang.ArithmeticException: Hey!!</span><br><span class="line">	at com.bennyhuo.coroutines.sample2.exceptions.ScopesKt$main$2$1$1.invokeSuspend(Scopes.kt:17)</span><br><span class="line">	at kotlin.coroutines.jvm.internal.BaseContinuationImpl.resumeWith(ContinuationImpl.kt:33)</span><br><span class="line">	at kotlinx.coroutines.DispatchedTask.run(Dispatched.kt:238)</span><br><span class="line">	at kotlinx.coroutines.scheduling.CoroutineScheduler.runSafely(CoroutineScheduler.kt:594)</span><br><span class="line">	at kotlinx.coroutines.scheduling.CoroutineScheduler.access$runSafely(CoroutineScheduler.kt:60)</span><br><span class="line">	at kotlinx.coroutines.scheduling.CoroutineScheduler$Worker.run(CoroutineScheduler.kt:742)</span><br><span class="line">11:52:49:915 [DefaultDispatcher-worker-3 @coroutine#2] 9</span><br><span class="line">11:52:49:915 [DefaultDispatcher-worker-3 @coroutine#2] 11</span><br><span class="line">11:52:49:915 [DefaultDispatcher-worker-3 @coroutine#2] 13</span><br></pre></td></tr></table></figure><p>我们可以看到，1-8 的输出其实没有本质区别，顺序上的差异是线程调度的前后造成的，并不会影响协程的语义。差别主要在于 9 与 10、11与12的区别，如果把 scope 换成 <code>supervisorScope</code>，我们发现 ③ 的异常并没有影响作用域以及作用域内的其他子协程的执行，也就是我们所说的“自作自受”。</p><p>这个例子其实我们再稍做一些改动，为 ② 和 ③ 增加一个 <code>CoroutineExceptionHandler</code>，就可以证明我们前面提到的另外一个结论：</p><p>首先我们定义一个 <code>CoroutineExceptionHandler</code>，我们通过上下文获取一下异常对应的协程的名字：</p><figure class="highlight kotlin"><table><tr><td class="gutter"><pre><span class="line">1</span><br><span class="line">2</span><br><span class="line">3</span><br></pre></td><td class="code"><pre><span class="line"><span class="keyword">val</span> exceptionHandler = CoroutineExceptionHandler &#123; coroutineContext, throwable -&gt;</span><br><span class="line">    log(<span class="string">&quot;<span class="subst">$&#123;coroutineContext[CoroutineName]&#125;</span> <span class="variable">$throwable</span>&quot;</span>)</span><br><span class="line">&#125;</span><br></pre></td></tr></table></figure><p>接着，基于前面的例子我们为 ② 和 ③ 添加 <code>CoroutineExceptionHandler</code> 和名字：</p><figure class="highlight kotlin"><table><tr><td class="gutter"><pre><span class="line">1</span><br><span class="line">2</span><br><span class="line">3</span><br><span class="line">4</span><br><span class="line">5</span><br><span class="line">6</span><br><span class="line">7</span><br><span class="line">8</span><br></pre></td><td class="code"><pre><span class="line">...</span><br><span class="line">supervisorScope &#123; <span class="comment">//①</span></span><br><span class="line">    log(<span class="number">2</span>)</span><br><span class="line">    launch(exceptionHandler + CoroutineName(<span class="string">&quot;②&quot;</span>)) &#123; <span class="comment">// ②</span></span><br><span class="line">        log(<span class="number">3</span>)</span><br><span class="line">        launch(exceptionHandler + CoroutineName(<span class="string">&quot;③&quot;</span>)) &#123; <span class="comment">// ③</span></span><br><span class="line">            log(<span class="number">4</span>)</span><br><span class="line">...</span><br></pre></td></tr></table></figure><p>再运行这段程序，结果就比较有意思了：</p><figure class="highlight plaintext"><table><tr><td class="gutter"><pre><span class="line">1</span><br><span class="line">2</span><br><span class="line">3</span><br></pre></td><td class="code"><pre><span class="line">...</span><br><span class="line">07:30:11:519 [DefaultDispatcher-worker-1] CoroutineName(②) java.lang.ArithmeticException: Hey!!</span><br><span class="line">...</span><br></pre></td></tr></table></figure><p>我们发现触发的 <code>CoroutineExceptionHandler</code> 竟然是协程 ② 的，意外吗？不意外，因为我们前面已经提到，对于 <code>supervisorScope</code> 的子协程 （例如 ②）的子协程（例如 ③），如果没有明确指出，它是遵循默认的作用于规则的，也就是 <code>coroutineScope</code> 的规则了，出现未捕获的异常会尝试传递给父协程并尝试取消父协程。</p><p>究竟使用什么 Scope，大家自己根据实际情况来确定，我给出一些建议：</p><ul><li>对于没有协程作用域，但需要启动协程的时候，适合用 GlobalScope</li><li>对于已经有协程作用域的情况（例如通过 GlobalScope 启动的协程体内），直接用协程启动器启动</li><li>对于明确要求子协程之间相互独立不干扰时，使用 supervisorScope</li><li>对于通过标准库 API 创建的协程，这样的协程比较底层，没有 Job、作用域等概念的支撑，例如我们前面提到过 suspend main 就是这种情况，对于这种情况优先考虑通过 coroutineScope 创建作用域；更进一步，大家尽量不要直接使用标准库 API，除非你对 Kotlin 的协程机制非常熟悉。</li></ul><p>当然，对于可能出异常的情况，请大家尽量做好异常处理，不要将问题复杂化。</p><h3 id="5-join-和-await"><a href="#5-join-和-await" class="headerlink" title="5. join 和 await"></a>5. join 和 await</h3><p>前面我们举例子一直用的是 <code>launch</code>，启动协程其实常用的还有 <code>async</code>、<code>actor</code> 和 <code>produce</code>，其中 <code>actor</code> 和 <code>launch</code> 的行为类似，在未捕获的异常出现以后，会被当做为处理的异常抛出，就像前面的例子那样。而 <code>async</code> 和 <code>produce</code> 则主要是用来输出结果的，他们内部的异常只在外部消费他们的结果时抛出。这两组协程的启动器，你也可以认为分别是“消费者”和“生产者”，消费者异常立即抛出，生产者只有结果消费时抛出异常。</p><blockquote><p><code>actor</code> 和 <code>produce</code> 这两个 API 目前处于比较微妙的境地，可能会被废弃或者后续提供替代方案，不建议大家使用，我们在这里就不展开细讲了。</p></blockquote><p>那么消费结果指的是什么呢？对于 <code>async</code> 来讲，就是 <code>await</code>，例如：</p><figure class="highlight kotlin"><table><tr><td class="gutter"><pre><span class="line">1</span><br><span class="line">2</span><br><span class="line">3</span><br><span class="line">4</span><br><span class="line">5</span><br><span class="line">6</span><br><span class="line">7</span><br><span class="line">8</span><br><span class="line">9</span><br><span class="line">10</span><br><span class="line">11</span><br></pre></td><td class="code"><pre><span class="line"><span class="keyword">suspend</span> <span class="function"><span class="keyword">fun</span> <span class="title">main</span><span class="params">()</span></span> &#123;</span><br><span class="line">    <span class="keyword">val</span> deferred = GlobalScope.async&lt;<span class="built_in">Int</span>&gt; &#123; </span><br><span class="line">        <span class="keyword">throw</span> ArithmeticException()</span><br><span class="line">    &#125;</span><br><span class="line">    <span class="keyword">try</span> &#123;</span><br><span class="line">        <span class="keyword">val</span> value = deferred.await()</span><br><span class="line">        log(<span class="string">&quot;1. <span class="variable">$value</span>&quot;</span>)</span><br><span class="line">    &#125; <span class="keyword">catch</span> (e: Exception) &#123;</span><br><span class="line">        log(<span class="string">&quot;2. <span class="variable">$e</span>&quot;</span>)</span><br><span class="line">    &#125;</span><br><span class="line">&#125;</span><br></pre></td></tr></table></figure><p>这个从逻辑上很好理解，我们调用 <code>await</code> 时，期望 <code>deferred</code> 能够给我们提供一个合适的结果，但它因为出异常，没有办法做到这一点，因此只好给我们丢出一个异常了。</p><figure class="highlight plaintext"><table><tr><td class="gutter"><pre><span class="line">1</span><br></pre></td><td class="code"><pre><span class="line">13:25:14:693 [main] 2. java.lang.ArithmeticException</span><br></pre></td></tr></table></figure><p>我们自己实现的 <code>getUserCoroutine</code> 也属于类似的情况，在获取结果时，如果请求出了异常，我们就只能拿到一个异常，而不是正常的结果。相比之下，<code>join</code> 就有趣的多了，它只关注是否执行完，至于是因为什么完成，它不关心，因此如果我们在这里替换成 <code>join</code>：</p><figure class="highlight kotlin"><table><tr><td class="gutter"><pre><span class="line">1</span><br><span class="line">2</span><br><span class="line">3</span><br><span class="line">4</span><br><span class="line">5</span><br><span class="line">6</span><br><span class="line">7</span><br><span class="line">8</span><br><span class="line">9</span><br><span class="line">10</span><br><span class="line">11</span><br></pre></td><td class="code"><pre><span class="line"><span class="keyword">suspend</span> <span class="function"><span class="keyword">fun</span> <span class="title">main</span><span class="params">()</span></span> &#123;</span><br><span class="line">    <span class="keyword">val</span> deferred = GlobalScope.async&lt;<span class="built_in">Int</span>&gt; &#123;</span><br><span class="line">        <span class="keyword">throw</span> ArithmeticException()</span><br><span class="line">    &#125;</span><br><span class="line">    <span class="keyword">try</span> &#123;</span><br><span class="line">        deferred.join()</span><br><span class="line">        log(<span class="number">1</span>)</span><br><span class="line">    &#125; <span class="keyword">catch</span> (e: Exception) &#123;</span><br><span class="line">        log(<span class="string">&quot;2. <span class="variable">$e</span>&quot;</span>)</span><br><span class="line">    &#125;</span><br><span class="line">&#125;</span><br></pre></td></tr></table></figure><p>我们就会发现，异常被吞掉了！</p><figure class="highlight plaintext"><table><tr><td class="gutter"><pre><span class="line">1</span><br></pre></td><td class="code"><pre><span class="line">13:26:15:034 [main] 1</span><br></pre></td></tr></table></figure><p>如果例子当中我们用 <code>launch</code> 替换 <code>async</code>，<code>join</code> 处仍然不会有任何异常抛出，还是那句话，它只关心有没有完成，至于怎么完成的它不关心。不同之处在于， <code>launch</code> 中未捕获的异常与 <code>async</code> 的处理方式不同，<code>launch</code> 会直接抛出给父协程，如果没有父协程（顶级作用域中）或者处于 <code>supervisorScope</code> 中父协程不响应，那么就交给上下文中指定的 <code>CoroutineExceptionHandler</code>处理，如果没有指定，那传给全局的 <code>CoroutineExceptionHandler</code> 等等，而 <code>async</code> 则要等 <code>await</code> 来消费。</p><blockquote><p>不管是哪个启动器，在应用了作用域之后，都会按照作用域的语义进行异常扩散，进而触发相应的取消操作，对于 <code>async</code> 来说就算不调用 <code>await</code> 来获取这个异常，它也会在 <code>coroutineScope</code> 当中触发父协程的取消逻辑，这一点请大家注意。</p></blockquote><h3 id="6-小结"><a href="#6-小结" class="headerlink" title="6. 小结"></a>6. 小结</h3><p>这一篇我们讲了协程的异常处理。这一块儿稍微显得有点儿复杂，但仔细理一下主要有三条线：</p><ol><li><strong>协程内部异常处理流程</strong>：launch 会在内部出现未捕获的异常时尝试触发对父协程的取消，能否取消要看作用域的定义，如果取消成功，那么异常传递给父协程，否则传递给启动时上下文中配置的 CoroutineExceptionHandler 中，如果没有配置，会查找全局（JVM上）的 CoroutineExceptionHandler 进行处理，如果仍然没有，那么就将异常交给当前线程的 UncaughtExceptionHandler 处理；而 async 则在未捕获的异常出现时同样会尝试取消父协程，但不管是否能够取消成功都不会后其他后续的异常处理，直到用户主动调用 await 时将异常抛出。</li><li><strong>异常在作用域内的传播</strong>：当协程出现异常时，会根据当前作用域触发异常传递，GlobalScope 会创建一个独立的作用域，所谓“自成一派”，而 在 coroutineScope 当中协程异常会触发父协程的取消，进而将整个协程作用域取消掉，如果对 coroutineScope 整体进行捕获，也可以捕获到该异常，所谓“一损俱损”；如果是 supervisorScope，那么子协程的异常不会向上传递，所谓“自作自受”。</li><li><strong>join 和 await 的不同</strong>：join 只关心协程是否执行完，await 则关心运行的结果，因此 join 在协程出现异常时也不会抛出该异常，而 await 则会；考虑到作用域的问题，如果协程抛异常，可能会导致父协程的取消，因此调用 join 时尽管不会对协程本身的异常进行抛出，但如果 join 调用所在的协程被取消，那么它会抛出取消异常，这一点需要留意。</li></ol><p>如果大家能把这三点理解清楚了，那么协程的异常处理可以说就非常清晰了。文中因为异常传播的原因，我们提到了取消，但没有展开详细讨论，后面我们将会专门针对取消输出一篇文章，帮助大家加深理解。</p><h3 id="附加说明"><a href="#附加说明" class="headerlink" title="附加说明"></a>附加说明</h3><p>join 在父协程被取消时有一个 bug 会导致不抛出取消异常，我在准备本文时发现该问题，目前已经提交到官方并得到了修复，预计合入到 1.2.1 发版，大家有兴趣可以查看这个 issue：<a target="_blank" rel="noopener" href="https://github.com/Kotlin/kotlinx.coroutines/issues/1123">No CancellationException thrown when join on a crashed Job</a>。</p><p>当然，这个 bug 对于生成环境的影响很小，大家也不要担心。</p><hr><h2 id="关于作者"><a href="#关于作者" class="headerlink" title="关于作者"></a>关于作者</h2><p><strong>霍丙乾 bennyhuo</strong>，Google 开发者专家（Kotlin 方向）；<strong>《深入理解 Kotlin 协程》</strong> 作者（机械工业出版社，2020.6）；<strong>《深入实践 Kotlin 元编程》</strong> 作者（机械工业出版社，2023.8）；移动客户端工程师，先后就职于腾讯地图、猿辅导、腾讯视频。</p><ul><li>GitHub：<a target="_blank" rel="noopener" href="https://github.com/bennyhuo">https://github.com/bennyhuo</a></li><li>博客：<a href="https://www.bennyhuo.com/">https://www.bennyhuo.com</a></li><li>bilibili：<a target="_blank" rel="noopener" href="https://space.bilibili.com/28615855"><strong>霍丙乾 bennyhuo</strong></a></li><li>微信公众号：<strong>霍丙乾 bennyhuo</strong></li></ul></div><footer class="post-footer"><div class="post-nav"><div class="post-nav-item"><a href="/2019/04/11/coroutine-dispatchers/" rel="prev" title="破解 Kotlin 协程（3）：协程调度篇"><i class="fa fa-chevron-left"></i> 破解 Kotlin 协程（3）：协程调度篇</a></div><div class="post-nav-item"><a href="/2019/04/30/coroutine-cancellation/" rel="next" title="破解 Kotlin 协程（5）：协程取消篇">破解 Kotlin 协程（5）：协程取消篇 <i class="fa fa-chevron-right"></i></a></div></div></footer></article></div><div class="comments gitalk-container"></div></div></main><footer class="footer"><div class="footer-inner"><div class="copyright">&copy; 2018 – <span itemprop="copyrightYear">2025</span> <span class="with-love"><i class="fa fa-heart"></i> </span><span class="author" itemprop="copyrightHolder">Benny Huo</span></div><div class="wordcount"><span class="post-meta-item"><span class="post-meta-item-icon"><i class="fa fa-chart-line"></i> </span><span title="站点总字数">497k</span> </span><span class="post-meta-item"><span class="post-meta-item-icon"><i class="fa fa-coffee"></i> </span><span title="站点阅读时长">15:04</span></span></div><div class="powered-by">由 <a href="https://hexo.io/" rel="noopener" target="_blank">Hexo</a> & <a href="https://theme-next.js.org/pisces/" rel="noopener" target="_blank">NexT.Pisces</a> 强力驱动</div></div></footer><div class="back-to-top" role="button" aria-label="返回顶部"><i class="fa fa-arrow-up fa-lg"></i> <span>0%</span></div><noscript><div class="noscript-warning">Theme NexT works best with JavaScript enabled</div></noscript><script src="https://cdnjs.cloudflare.com/ajax/libs/animejs/3.2.1/anime.min.js" integrity="sha256-XL2inqUJaslATFnHdJOi9GfQ60on8Wx1C2H8DYiN1xY=" crossorigin="anonymous"></script><script src="/js/comments.js"></script><script src="/js/utils.js"></script><script src="/js/motion.js"></script><script src="/js/next-boot.js"></script><script class="next-config" data-name="leancloud_visitors" type="application/json">{"enable":true,"app_id":"FicBFjnnYPST748WV6dmgumh-gzGzoHsz","app_key":"9GE81hTRn176FdLAdUrJBWON","server_url":null,"security":false}</script><script src="/js/third-party/statistics/lean-analytics.js"></script><link rel="stylesheet" href="https://cdnjs.cloudflare.com/ajax/libs/gitalk/1.8.0/gitalk.css" integrity="sha256-AJnUHL7dBv6PGaeyPQJcgQPDjt/Hn/PvYZde1iqfp8U=" crossorigin="anonymous"><script class="next-config" data-name="gitalk" type="application/json">{"enable":true,"github_id":"bennyhuo","repo":"Bennyhuo","client_id":"7d2353275afc8d2a5ba3","client_secret":"b43a5cabf6064d62cd3fea35adde9609ca49887f","admin_user":"bennyhuo","distraction_free_mode":true,"proxy":"https://silent-lake-5dba.bennyhuo.workers.dev/?https://github.com/login/oauth/access_token","language":"zh-CN","owner":"bennyhuo","js":{"url":"https://cdnjs.cloudflare.com/ajax/libs/gitalk/1.8.0/gitalk.min.js","integrity":"sha256-MVK9MGD/XJaGyIghSVrONSnoXoGh3IFxLw0zfvzpxR4="},"path_md5":"18a3ca3a767e869bdec51082fe83e9cf"}</script><script src="/js/third-party/comments/gitalk.js"></script></body></html>